
<mujoco>
<worldbody>
<light diffuse=".5 .5 .5" pos="0 0 2" dir="0 -1 0"/>
<geom type="plane" size="20 20 0.1" rgba="0.8 0.8 0.8 1"/>
<body name = "base0" pos = "0 0 1.2232851488841479">
<geom type = "box" size = "0.11341535325259047 0.1466383679113061 0.22328514888414797" rgba = "0.3 0.3 0.3 1"/>
<joint name = "jbase" type = "free" axis = "0 1 0" pos = "0 0 0"/>
<body name = "limb_base_00" pos = "-0.275694044264864 0.022742799701064072 -0.07784688348583041">
<geom type = "box" size = "0.1622786910122735 0.011120011477672886 0.240016273816482" rgba = "0.9095735509817408 0.07777182260872761 0.8422425473591865 1"/>
<joint name = "jlimb_base_0" type = "hinge" axis = "0 0 1" pos = "0.1622786910122735 0 0"/>
<body name = "limb_limb_base_0_00" pos = "-0.26256869525101556 0.07774133696793532 0.1598757475736801">
<geom type = "box" size = "0.1002900042387421 0.1645879624721084 0.1550036573916251" rgba = "0.15060565618519672 0.05825702949955114 0.0007472435274801237 1"/>
<joint name = "jlimb_limb_base_0_0" type = "hinge" axis = "0 1 0" pos = "0.1002900042387421 0 0"/>
<body name = "limb_limb_base_0_10" pos = "0.0525472325944719 0.1272777702668944 -0.037386585428777985">
<geom type = "box" size = "0.10118131368056531 0.11615775878922152 0.10419036689708217" rgba = "0.583225364235599 0.3809597812105624 0.8523948018712862 1"/>
<joint name = "jlimb_limb_base_0_1" type = "hinge" axis = "0 1 0" pos = "0 -0.11615775878922152 0"/>
<body name = "limb_limb_limb_base_0_1_00" pos = "0.0797581249706598 -0.4083119667663266 0.15357199748841982">
<geom type = "box" size = "0.13933556602282052 0.29215420797710506 0.25498046336958846" rgba = "0.4454256877548809 0.1216105158218429 0.16612481999382778 1"/>
<joint name = "jlimb_limb_limb_base_0_1_0" type = "hinge" axis = "1 0 0" pos = "0 0.29215420797710506 0"/>
</body>
</body>
</body>
</body>
</body>
</worldbody>
<actuator>
<motor name = "mbase" joint = "jbase" gear = "1" ctrllimited = "true" ctrlrange = "-1 1"/>
<motor name = "mlimb_base_0" joint = "jlimb_base_0" gear = "1" ctrllimited = "true" ctrlrange = "-1 1"/>
<motor name = "mlimb_limb_base_0_0" joint = "jlimb_limb_base_0_0" gear = "3" ctrllimited = "true" ctrlrange = "-3 3"/>
<motor name = "mlimb_limb_base_0_1" joint = "jlimb_limb_base_0_1" gear = "3" ctrllimited = "true" ctrlrange = "-3 3"/>
<motor name = "mlimb_limb_limb_base_0_1_0" joint = "jlimb_limb_limb_base_0_1_0" gear = "4" ctrllimited = "true" ctrlrange = "-4 4"/>
</actuator>
</mujoco>