
<mujoco>
<worldbody>
<light diffuse=".5 .5 .5" pos="0 0 2" dir="0 -1 0"/>
<geom type="plane" size="20 20 0.1" rgba="0.8 0.8 0.8 1"/>
<body name = "base_new_new_new_new0" pos = "0.05588096026823014 -0.033261968569213644 1.026972721589077">
<geom type = "box" size = "0.04926943601255352 0.03376851213170162 0.12002593638346606" rgba = "0.3 0.3 0.3 1"/>
<joint name = "jbase_new_new_new_new" type = "free" axis = "0 1 0" pos = "0 0 -0.12002593638346606"/>
<body name = "limb_base_0_new_new_new_new0" pos = "-0.05790978217474455 -0.09562273360430937 0.12752743628909338">
<geom type = "box" size = "0.09924998455712356 0.21993695556898457 0.17931772572604482" rgba = "0.38644104266266965 0.8193153465813626 0.141726141182838 1"/>
<joint name = "jlimb_base_0_new_new_new_new" type = "hinge" axis = "0 0 1" pos = "0.027086678694108076 -0.19560912282762402 -0.07762214283870708"/>
<body name = "limb_limb_base_0_0_new_new_new_new0" pos = "0.3055550505088193 0.15520907284754443 0.1003874301759297">
<geom type = "box" size = "0.3302046288434152 0.2715981268890886 0.29321605954781826" rgba = "0.39147649402927287 0.2097390937876067 0.532206807242542 1"/>
<joint name = "jlimb_limb_base_0_0_new_new_new_new" type = "hinge" axis = "1 0 0" pos = "-0.29613908232751407 0.030035771251140944 -0.02195344257545962"/>
</body>
</body>
<body name = "limb_base_1_new_new_new_new0" pos = "-0.05484812233419206 0.11093521095678748 0.42517022904442103">
<geom type = "box" size = "0.2609287323415471 0.19851756929072836 0.35807255633882223" rgba = "0.1286278654289229 0.47413682189904105 0.6417214875229027 1"/>
<joint name = "jlimb_base_1_new_new_new_new" type = "hinge" axis = "0 1 0" pos = "0.04274086724655903 0.09393728393079723 -0.33875947105623955"/>
<body name = "limb_limb_base_1_0_new_new_new_new0" pos = "-0.05697368624094958 -0.1970975643991231 0.5288503427099852">
<geom type = "box" size = "0.15697782892275083 0.18119445137684353 0.29870178695357175" rgba = "0.2263631166680592 0.97638490618588 0.25253284047695923 1"/>
<joint name = "jlimb_limb_base_1_0_new_new_new_new" type = "hinge" axis = "1 0 0" pos = "-0.020312895215137957 0.06778792831073843 -0.25031190225626937"/>
</body>
</body>
</body>
</worldbody>
<actuator>
<motor name = "mbase_new_new_new_new" joint = "jbase_new_new_new_new" gear = "1" ctrllimited = "true" ctrlrange = "-1 1"/>
<motor name = "mlimb_base_0_new_new_new_new" joint = "jlimb_base_0_new_new_new_new" gear = "3" ctrllimited = "true" ctrlrange = "-3.0 3.0"/>
<motor name = "mlimb_limb_base_0_0_new_new_new_new" joint = "jlimb_limb_base_0_0_new_new_new_new" gear = "5" ctrllimited = "true" ctrlrange = "-5.0 5.0"/>
<motor name = "mlimb_base_1_new_new_new_new" joint = "jlimb_base_1_new_new_new_new" gear = "4" ctrllimited = "true" ctrlrange = "-4.0 4.0"/>
<motor name = "mlimb_limb_base_1_0_new_new_new_new" joint = "jlimb_limb_base_1_0_new_new_new_new" gear = "5" ctrllimited = "true" ctrlrange = "-5.0 5.0"/>
</actuator>
</mujoco>