<mujoco>
              <worldbody>
              <light diffuse=".5 .5 .5" pos="0 0 2" dir="0 -1 0"/>
              <geom type="plane" size="10 10 0.1" rgba="0 0 0.9 1"/><body name = "base" pos = "0 0 1.1584101667625992">
<geom type = "box" size = "0.1071399119765049 0.2369625386624173 0.15841016676259914" rgba = "0.3 0.3 0.3 1"/><joint name = "jbasev0" type = "free" axis = "0 1 0" pos = "0 0 -0.15841016676259914"/>
<body name = "limb_base_0" pos = "-0.026663696219770553 0.15846304470883169 0.3288517180124222">
<geom type = "box" size = "0.05698915433762399 0.09708645844456527 0.17044155124982305" rgba = "0.22810707065196956 0.44473116780041044 0.8782727590302226 1"/><joint name = "jlimb_base_0v0" type = "hinge" axis = "1 0 0" pos = "0 0 -0.17044155124982305"/>
<body name = "limb_limb_base_0_0" pos = "0.1163466263253292 0.016197069635034537 0.2338347864718008">
<geom type = "box" size = "0.2628063104669942 0.11702678861108201 0.06339323522197776" rgba = "0.6107734519463695 0.14294471789392105 0.47308571382102216 1"/><joint name = "jlimb_limb_base_0_0v0" type = "hinge" axis = "0 0 1" pos = "0 0 -0.06339323522197776"/>
<body name = "limb_limb_limb_base_0_0_0" pos = "0.04453840680001913 -0.3092242351647322 0.0741269254036375">
<geom type = "box" size = "0.12625882404134028 0.19219744655365015 0.18076299576617394" rgba = "0.7113049097807993 0.48500665525007114 0.728565061730208 1"/><joint name = "jlimb_limb_limb_base_0_0_0v0" type = "hinge" axis = "0 0 1" pos = "0 0.19219744655365015 0"/>
</body>
<body name = "limb_limb_limb_base_0_0_1" pos = "-0.217775582746292 -0.06988091627362789 0.08842945001401756">
<geom type = "box" size = "0.2010351244072233 0.12210787859420891 0.0250362147920398" rgba = "0.9219247887543414 0.8171355212953039 0.8094646615180843 1"/><joint name = "jlimb_limb_limb_base_0_0_1v0" type = "hinge" axis = "0 0 1" pos = "0 0 -0.0250362147920398"/>
</body>
</body>
<body name = "limb_limb_base_0_0" pos = "-0.06863022071378837 0.17185787715441056 -0.0721789390753701">
<geom type = "box" size = "0.16473694884936327 0.07477141870984529 0.0549290202648484" rgba = "0.7566501378368917 0.4985669660787436 0.39080217830727815 1"/><joint name = "jlimb_limb_base_0_0v0" type = "hinge" axis = "1 0 0" pos = "0 -0.07477141870984529 0"/>
<body name = "limb_limb_limb_base_0_0_0" pos = "-0.027514267585395605 -0.09849223645818352 0.123300883041755">
<geom type = "box" size = "0.05091179526409444 0.02372081774833823 0.27695049257225784" rgba = "0.9576532473303071 0.09960143788943476 0.6915538577539851 1"/><joint name = "jlimb_limb_limb_base_0_0_0v0" type = "hinge" axis = "1 0 0" pos = "0 0.02372081774833823 0"/>
</body>
<body name = "limb_limb_limb_base_0_0_1" pos = "0.19117230864830886 -0.0812233825275535 -0.024797516438992324">
<geom type = "box" size = "0.2697939848795169 0.006451963817708206 0.0950715606144381" rgba = "0.2832829356587996 0.4135303764639173 0.5884026492945083 1"/><joint name = "jlimb_limb_limb_base_0_0_1v0" type = "hinge" axis = "0 1 0" pos = "0 0.006451963817708206 0"/>
</body>
</body>
<body name = "limb_limb_base_0_1" pos = "0.010080723272516566 -0.2635841632681524 -0.02026072132436805">
<geom type = "box" size = "0.25989796712916563 0.16649770482358714 0.009626992607882467" rgba = "0.7067767580437291 0.3360917276581432 0.09002846047334101 1"/><joint name = "jlimb_limb_base_0_1v0" type = "hinge" axis = "0 1 0" pos = "0 0.16649770482358714 0"/>
<body name = "limb_limb_limb_base_0_1_0" pos = "-0.37673780947351754 0.14003142308946137 -0.013885282630856836">
<geom type = "box" size = "0.11683984234435191 0.2221499011295832 0.047015540774191976" rgba = "0.1467217691768249 0.0519477446973865 0.2034152568048907 1"/><joint name = "jlimb_limb_limb_base_0_1_0v0" type = "hinge" axis = "0 0 1" pos = "0.11683984234435191 0 0"/>
</body>
</body>
</body>
<body name = "limb_base_1" pos = "-0.00547630014391704 0.08487494618254217 0.20755121153018494">
<geom type = "box" size = "0.06541286776524116 0.196829965198241 0.049141044767585795" rgba = "0.47456271948703965 0.8311143127566925 0.5351695607223479 1"/><joint name = "jlimb_base_1v0" type = "hinge" axis = "0 0 1" pos = "0 0 -0.049141044767585795"/>
</body>
</body>
</worldbody>
<actuator>
<motor name = "mbasev0" joint = "jbasev0" gear = "1" ctrllimited = "true" ctrlrange = "-1 1"/>
<motor name = "mlimb_base_0v0" joint = "jlimb_base_0v0" gear = "5" ctrllimited = "true" ctrlrange = "-5 5"/>
<motor name = "mlimb_limb_base_0_0v0" joint = "jlimb_limb_base_0_0v0" gear = "5" ctrllimited = "true" ctrlrange = "-5 5"/>
<motor name = "mlimb_limb_limb_base_0_0_0v0" joint = "jlimb_limb_limb_base_0_0_0v0" gear = "5" ctrllimited = "true" ctrlrange = "-5 5"/>
<motor name = "mlimb_limb_limb_base_0_0_1v0" joint = "jlimb_limb_limb_base_0_0_1v0" gear = "5" ctrllimited = "true" ctrlrange = "-5 5"/>
<motor name = "mlimb_limb_base_0_0v0" joint = "jlimb_limb_base_0_0v0" gear = "5" ctrllimited = "true" ctrlrange = "-5 5"/>
<motor name = "mlimb_limb_limb_base_0_0_0v0" joint = "jlimb_limb_limb_base_0_0_0v0" gear = "5" ctrllimited = "true" ctrlrange = "-5 5"/>
<motor name = "mlimb_limb_limb_base_0_0_1v0" joint = "jlimb_limb_limb_base_0_0_1v0" gear = "5" ctrllimited = "true" ctrlrange = "-5 5"/>
<motor name = "mlimb_limb_base_0_1v0" joint = "jlimb_limb_base_0_1v0" gear = "5" ctrllimited = "true" ctrlrange = "-5 5"/>
<motor name = "mlimb_limb_limb_base_0_1_0v0" joint = "jlimb_limb_limb_base_0_1_0v0" gear = "5" ctrllimited = "true" ctrlrange = "-5 5"/>
<motor name = "mlimb_base_1v0" joint = "jlimb_base_1v0" gear = "5" ctrllimited = "true" ctrlrange = "-5 5"/>
</actuator>
</mujoco>