<mujoco>
    <worldbody>
        
        <light diffuse="0.5 0.5 0.5" pos="0 0 2" dir="0 -1 0"/>
        <geom type="plane" size="1 1 0.1" rgba="0.9 0 0 1"/>

        <body pos="0 0 0.1">
			<joint type="slide" axis="1 0 0"/>
			<joint type="slide" axis="0 0 1"/>
			<joint type="hinge" axis="0 -1 0"/>
			<geom type="sphere" size=".1"/>
            <body pos="0 0.1 0">
                <geom type="box" size=".05 .05 .05"/>
            </body>
		</body>

        
        
    </worldbody>
</mujoco>
