<mujoco>
              <worldbody>
              <light diffuse=".5 .5 .5" pos="0 0 2" dir="0 -1 0"/>
              <geom type="plane" size="10 10 0.1" rgba="0 0 0.9 1"/><body name = "head" pos = "0 0 0.3">
<geom type = "box" size = "0.1 0.1 0.1" rgba = "1 0 0 1"/><joint name = "jhead" type = "free" axis = "0 1 0" pos = "0 0 0"/>
<body name = "foot" pos = "0 0.3 0.2">
<geom type = "box" size = "0.1 0.2 0.1" rgba = "0 1 0 1"/><joint name = "jfoot" type = "hinge" axis = "1 0 0" pos = "0 -0.2 -0.1"/>
</body>
<body name = "foot2" pos = "0 -0.3 0.2">
<geom type = "box" size = "0.1 0.2 0.1" rgba = "0 1 0 1"/><joint name = "jfoot2" type = "hinge" axis = "1 0 0" pos = "0 0.2 -0.1"/>
</body>
</body>
</worldbody>
<actuator>
<motor name = "mhead" joint = "jhead" gear = "0" + ctrlrange = "0 0"/>
<motor name = "mfoot" joint = "jfoot" gear = "20" + ctrlrange = "0 0"/>
<motor name = "mfoot2" joint = "jfoot2" gear = "20" + ctrlrange = "0 0"/>
</actuator>
</mujoco>